Workbook
Name \0: #REF!
Name \a: #REF!
Name \b: #REF!
Name \c: #REF!
Name \D: #REF!
Name \E: #REF!
Name \F: #REF!
Name \G: #REF!
Name \H: #REF!
Name \I: #REF!
Name \J: #REF!
Name \K: #REF!
Name \L: #REF!
Name \M: #REF!
Name \N: #REF!
Name \P: #REF!
Name \q: #REF!
Name \r: #REF!
Name \S: #REF!
Name \t: #REF!
Name \U: #REF!
Name \V: #REF!
Name \w: #REF!
Name \x: #REF!
Name \y: #REF!
Name \Z: #REF!
Name ___________________________________top50: #REF!
Name _________________________________top50: #REF!
Name _______________________________top50: #REF!
Name ______________________________AB113812: #REF!
Name _____________________________AB113812: #REF!
Name ____________________________AB113812: #REF!
Name _________________________top50: #REF!
Name _______________________AB113812: #REF!
Name _____________________top50: #REF!
Name ___________________top50: #REF!
Name __________________AB113812: #REF!
Name __________________top50: #REF!
Name ________________AB113812: #REF!
Name ______________AB113812: #REF!
Name ______________top50: #REF!
Name _____________AB113812: #REF!
Name ____________AB113812: #REF!
Name ____________top50: #REF!
Name ___________AB113812: #REF!
Name ___________top50: #REF!
Name __________AB113812: #REF!
Name __________top50: #REF!
Name _________AB113812: #REF!
Name _________top50: #REF!
Name ________AB113812: #REF!
Name ________top50: #REF!
Name _______AB113812: #REF!
Name _______top50: #REF!
Name ______AB113812: #REF!
Name ______top50: #REF!
Name ___DAT10: #REF!
Name ___DAT15: #REF!
Name ___DAT16: #REF!
Name ___DAT17: #REF!

Sheet Summary Rollforward
A1: Treya Partners
A2: Accounts Receivable Rollforward
A3: February 28, 2024
E5: 45535 | I5: September Activity | L5: 45565 | P5: October Activity | S5: 45596 | W5: November Activity | Z5: 45626 | AD5: December Activity | AI5: 45657 | AM5: January Activity | AQ5: 45688 | AU5: February Activity | AY5: 45716 | BC5: March Activity | BG5: 45747 | BK5: April Activity | BO5: 45777 | BS5: May Activity | BX5: 45808 | CB5: June Activity | CG5: 45838 | CK5: July Activity | CP5: 45869 | CT5: August Activity | CY5: 45900 | DC5: September Activity | DH5: 45930 | DL5: October Activity | DQ5: 45961 | DU5: November Activity | DZ5: 45991 | ED5: December Activity | EI5: 46022
B6: Client | C6: PE Sponsor | E6: Billed AR | F6: Unbilled AR | G6: Total AR | I6: Service Revenue Recorded | J6: Cash Collections | L6: Billed AR | M6: Unbilled AR | N6: Total AR | P6: Service Revenue Recorded | Q6: Cash Collections | S6: Billed AR | T6: Unbilled AR | U6: Total AR | W6: Revenue Recorded | X6: Cash Collections | Z6: Billed AR | AA6: Unbilled AR | AB6: Total AR | AD6: Revenue - Unbilled | AE6: Revenue Invoiced | AF6: Adjustments | AG6: Cash Collections | AI6: Billed AR | AJ6: Unbilled AR | AK6: Total AR | AM6: Revenue - Unbilled | AN6: Revenue Invoiced | AO6: Cash Collections | AQ6: Billed AR | AR6: Unbilled AR | AS6: Total AR | AU6: Revenue - Unbilled | AV6: Revenue Invoiced | AW6: Cash Collections | AY6: Billed AR | AZ6: Unbilled AR | BA6: Total AR | BC6: Revenue - Unbilled | BD6: Revenue Invoiced | BE6: Cash Collections | BG6: Billed AR | BH6: Unbilled AR | BI6: Total AR | BK6: Revenue - Unbilled | BL6: Revenue Invoiced | BM6: Cash Collections | BO6: Billed AR | BP6: Unbilled AR | BQ6: Total AR | BS6: Revenue - Unbilled | BT6: Revenue Invoiced | BU6: Cash Collections | BV6: Current Month Revenue | BX6: Billed AR | BY6: Unbilled AR | BZ6: Total AR | CB6: Revenue - Unbilled | CC6: Revenue Invoiced | CD6: Cash Collections | CE6: Current Month Revenue | CG6: Billed AR | CH6: Unbilled AR | CI6: Total AR | CK6: Revenue - Unbilled | CL6: Revenue Invoiced | CM6: Cash Collections | CN6: Current Month Revenue | CP6: Billed AR | CQ6: Unbilled AR | CR6: Total AR | CT6: Revenue - Unbilled | CU6: Revenue Invoiced | CV6: Cash Collections | CW6: Current Month Revenue | CY6: Billed AR | CZ6: Unbilled AR | DA6: Total AR | DC6: Revenue - Unbilled | DD6: Revenue Invoiced | DE6: Cash Collections | DF6: Current Month Revenue | DH6: Billed AR | DI6: Unbilled AR | DJ6: Total AR | DL6: Revenue - Unbilled | DM6: Revenue Invoiced | DN6: Cash Collections | DO6: Current Month Revenue | DQ6: Billed AR | DR6: Unbilled AR | DS6: Total AR | DU6: Revenue - Unbilled | DV6: Revenue Invoiced | DW6: Cash Collections | DX6: Current Month Revenue | DZ6: Billed AR | EA6: Unbilled AR | EB6: Total AR | ED6: Revenue - Unbilled | EE6: Revenue Invoiced | EF6: Cash Collections | EG6: Current Month Revenue | EI6: Billed AR | EJ6: Unbilled AR | EK6: Total AR
A7: Service Contracts
B8: Artisant Lane | C8: HWP | E8: 0 | F8: =+G8-E8 -> 146395.26 | G8: =+'AR Calculation - Service'!AM33 -> 146395.26 | L8: =+'Sep 30'!G6 -> 121395.26 | M8: =+N8-L8 -> 25000 | N8: =+G8+I8+J8 -> 146395.26 | Q8: =-'Oct Collections'!J8-'Oct Collections'!J9 -> -121395.26 | S8: 0 | T8: =+U8-S8 -> 25000 | U8: =+N8+P8+Q8 -> 25000 | W8: 0 | X8: =-'Oct Collections'!Q8-'Oct Collections'!Q9 -> 0 | Z8: 0 | AA8: =+AB8-Z8 -> 25000 | AB8: =+U8+W8+X8 -> 25000 | AD8: 0 | AF8: -25000 | AG8: =-'Oct Collections'!X8-'Oct Collections'!X9 -> 0 | AI8: 0 | AJ8: =+AK8-AI8 -> 1.4551915e-11 | AK8: =+AB8+AD8+AG8+AF8+AE8 -> 1.4551915e-11 | AM8: 0 | AO8: =-'Oct Collections'!AF8-'Oct Collections'!AF9 -> 0 | AQ8: =+AI8+AN8+AO8 -> 0 | AR8: =+AS8-AQ8 -> 1.4551915e-11 | AS8: =+AK8+AM8+AO8+AN8 -> 1.4551915e-11 | AU8: 0 | AW8: =-'Oct Collections'!AN8-'Oct Collections'!AN9 -> 0 | AY8: =+AQ8+AV8+AW8 -> 0 | AZ8: =+BA8-AY8 -> 1.4551915e-11 | BA8: =+AS8+AU8+AW8+AV8 -> 1.4551915e-11 | BC8: 0 | BG8: =+AY8+BD8+BE8 -> 0 | BH8: =+BI8-BG8 -> 1.4551915e-11 | BI8: =+BA8+BC8+BE8+BD8 -> 1.4551915e-11 | BO8: =+BG8+BL8+BM8 -> 0 | BP8: =+BQ8-BO8 -> 1.4551915e-11 | BQ8: =+BI8+BK8+BM8+BL8 -> 1.4551915e-11 | BS8: =BV8-BT8 -> 0 | BT8: 0 | BU8: 0 | BV8: =SUMIFS('Contract Data'!IP:IP,'Contract Data'!$C:$C,'Summary Rollforward'!$B8) -> 0 | BX8: =+BO8+BT8+BU8 -> 0 | BY8: =+BZ8-BX8 -> 1.4551915e-11 | BZ8: =+BQ8+BS8+BU8+BT8 -> 1.4551915e-11 | CB8: =CE8-CC8 -> 0 | CC8: =SUMIFS('June 25 Inv'!G:G,'June 25 Inv'!D:D,'Summary Rollforward'!$B8) -> 0 | CD8: =-SUMIFS('Jun25 Dep'!I:I,'Jun25 Dep'!F:F,'Summary Rollforward'!$B8) -> 0 | CE8: =SUMIFS('Contract Data'!IQ:IQ,'Contract Data'!$C:$C,'Summary Rollforward'!$B8) -> 0 | CG8: =+BX8+CC8+CD8 -> 0 | CH8: =+CI8-CG8 -> 1.4551915e-11 | CI8: =+BZ8+CB8+CD8+CC8 -> 1.4551915e-11 | CK8: =CN8-CL8 -> 0 | CL8: =SUMIFS('Jul 25 Inv'!H:H,'Jul 25 Inv'!E:E,'Summary Rollforward'!$B8) -> 0 | CM8: =-SUMIFS('Jul25 Dep'!J:J,'Jul25 Dep'!F:F,'Summary Rollforward'!$B8) -> 0 | CN8: =SUMIFS('Contract Data'!IR:IR,'Contract Data'!$C:$C,'Summary Rollforward'!$B8) -> 0 | CP8: =+CG8+CL8+CM8 -> 0 | CQ8: =+CR8-CP8 -> 1.4551915e-11 | CR8: =+CI8+CK8+CM8+CL8 -> 1.4551915e-11 | CT8: =CW8-CU8 -> 0 | CU8: =SUMIFS('Aug 25 Inv'!H:H,'Aug 25 Inv'!E:E,'Summary Rollforward'!$B8) -> 0 | CV8: =-SUMIFS('Aug25 Dep'!J:J,'Aug25 Dep'!F:F,'Summary Rollforward'!$B8) -> 0 | CW8: =SUMIFS('Contract Data'!IS:IS,'Contract Data'!$C:$C,'Summary Rollforward'!$B8) -> 0 | CY8: =+CP8+CU8+CV8 -> 0 | CZ8: =+DA8-CY8 -> 1.4551915e-11 | DA8: =+CR8+CT8+CV8+CU8 -> 1.4551915e-11 | DC8: =DF8-DD8 -> 0 | DD8: =SUMIFS('Sep 25 Inv'!H:H,'Sep 25 Inv'!E:E,'Summary Rollforward'!$B8) -> 0 | DE8: =-SUMIFS('Sep25 Dep'!J:J,'Sep25 Dep'!F:F,'Summary Rollforward'!$B8) -> 0 | DF8: =SUMIFS('Contract Data'!IT:IT,'Contract Data'!$C:$C,'Summary Rollforward'!$B8) -> 0 | DH8: =+CY8+DD8+DE8 -> 0 | DI8: =+DJ8-DH8 -> 1.4551915e-11 | DJ8: =+DA8+DC8+DE8+DD8 -> 1.4551915e-11 | DL8: =DO8-DM8 -> 0 | DM8: =SUMIFS('Oct 25 Inv'!H:H,'Oct 25 Inv'!E:E,'Summary Rollforward'!$B8) -> 0 | DN8: =-SUMIFS('Oct25 Dep'!J:J,'Oct25 Dep'!F:F,'Summary Rollforward'!$B8) -> 0 | DO8: =SUMIFS('Contract Data'!IU:IU,'Contract Data'!$C:$C,'Summary Rollforward'!$B8) -> 0 | DQ8: =+DH8+DM8+DN8 -> 0 | DR8: =+DS8-DQ8 -> 1.4551915e-11 | DS8: =+DJ8+DL8+DN8+DM8 -> 1.4551915e-11 | DU8: =DX8-DV8 -> 0 | DV8: =SUMIFS('Nov 25 Inv'!H:H,'Nov 25 Inv'!E:E,'Summary Rollforward'!$B8) -> 0 | DW8: =-SUMIFS('Nov25 Dep'!J:J,'Nov25 Dep'!F:F,'Summary Rollforward'!$B8) -> 0 | DX8: =SUMIFS('Contract Data'!IV:IV,'Contract Data'!$C:$C,'Summary Rollforward'!$B8) -> 0 | DZ8: =+DQ8+DV8+DW8 -> 0 | EA8: =+EB8-DZ8 -> 1.4551915e-11 | EB8: =+DS8+DU8+DW8+DV8 -> 1.4551915e-11 | ED8: =EG8-EE8 -> 0 | EE8: =SUMIFS('Dec 25 Inv'!H:H,'Dec 25 Inv'!E:E,'Summary Rollforward'!$B8) -> 0 | EF8: =-SUMIFS('Dec25 Dep'!I:I,'Dec25 Dep'!F:F,'Summary Rollforward'!$B8) -> 0 | EG8: =SUMIFS('Contract Data'!IW:IW,'Contract Data'!$C:$C,'Summary Rollforward'!$B8) -> 0 | EI8: =+DZ8+EE8+EF8 -> 0 | EJ8: =+EK8-EI8 -> 1.4551915e-11 | EK8: =+EB8+ED8+EF8+EE8 -> 1.4551915e-11
B9: Belt Power | C9: Platte River Equity | DL9: =DO9-DM9 -> -37000 | DM9: =SUMIFS('Oct 25 Inv'!H:H,'Oct 25 Inv'!E:E,'Summary Rollforward'!$B9) -> 52500 | DN9: =-SUMIFS('Oct25 Dep'!J:J,'Oct25 Dep'!F:F,'Summary Rollforward'!$B9) -> 0 | DO9: =SUMIFS('Contract Data'!IU:IU,'Contract Data'!$C:$C,'Summary Rollforward'!$B9) -> 15500 | DQ9: =+DH9+DM9+DN9 -> 52500 | DR9: =+DS9-DQ9 -> -37000 | DS9: =+DJ9+DL9+DN9+DM9 -> 15500 | DU9: =DX9-DV9 -> -21500 | DV9: =SUMIFS('Nov 25 Inv'!H:H,'Nov 25 Inv'!E:E,'Summary Rollforward'!$B9) -> 52500 | DW9: =-SUMIFS('Nov25 Dep'!J:J,'Nov25 Dep'!F:F,'Summary Rollforward'!$B9) -> -52500 | DX9: =SUMIFS('Contract Data'!IV:IV,'Contract Data'!$C:$C,'Summary Rollforward'!$B9) -> 31000 | DZ9: =+DQ9+DV9+DW9 -> 52500 | EA9: =+EB9-DZ9 -> -58500 | EB9: =+DS9+DU9+DW9+DV9 -> -6000 | ED9: =EG9-EE9 -> -21500 | EE9: =SUMIFS('Dec 25 Inv'!H:H,'Dec 25 Inv'!E:E,'Summary Rollforward'!$B9) -> 52500 | EF9: =-SUMIFS('Dec25 Dep'!I:I,'Dec25 Dep'!F:F,'Summary Rollforward'!$B9) -> -52500 | EG9: =SUMIFS('Contract Data'!IW:IW,'Contract Data'!$C:$C,'Summary Rollforward'!$B9) -> 31000 | EI9: =+DZ9+EE9+EF9 -> 52500 | EJ9: =+EK9-EI9 -> -80000 | EK9: =+EB9+ED9+EF9+EE9 -> -27500
B10: Bluum USA | C10: HIG Capital | BS10: =BV10-BT10 -> -107812.5 | BT10: 156250 | BU10: 0 | BV10: =SUMIFS('Contract Data'!IP:IP,'Contract Data'!C:C,'Summary Rollforward'!B10) -> 48437.5 | BX10: =+BO10+BT10+BU10 -> 156250 | BY10: =+BZ10-BX10 -> -107812.5 | BZ10: =+BQ10+BS10+BU10+BT10 -> 48437.5 | CB10: =CE10-CC10 -> 96875 | CC10: =SUMIFS('June 25 Inv'!G:G,'June 25 Inv'!D:D,'Summary Rollforward'!$B10) -> 0 | CD10: =-SUMIFS('Jun25 Dep'!I:I,'Jun25 Dep'!F:F,'Summary Rollforward'!$B10) -> 0 | CE10: =SUMIFS('Contract Data'!IQ:IQ,'Contract Data'!$C:$C,'Summary Rollforward'!$B10) -> 96875 | CG10: =+BX10+CC10+CD10 -> 156250 | CH10: =+CI10-CG10 -> -10937.5 | CI10: =+BZ10+CB10+CD10+CC10 -> 145312.5 | CK10: =CN10-CL10 -> 96875 | CL10: =SUMIFS('Jul 25 Inv'!H:H,'Jul 25 Inv'!E:E,'Summary Rollforward'!$B10) -> 0 | CM10: =-SUMIFS('Jul25 Dep'!J:J,'Jul25 Dep'!F:F,'Summary Rollforward'!$B10) -> -156250 | CN10: =SUMIFS('Contract Data'!IR:IR,'Contract Data'!$C:$C,'Summary Rollforward'!$B10) -> 96875 | CP10: =+CG10+CL10+CM10 -> 0 | CQ10: =+CR10-CP10 -> 85937.5 | CR10: =+CI10+CK10+CM10+CL10 -> 85937.5 | CT10: =CW10-CU10 -> 96875 | CU10: =SUMIFS('Aug 25 Inv'!H:H,'Aug 25 Inv'!E:E,'Summary Rollforward'!$B10) -> 0 | CV10: =-SUMIFS('Aug25 Dep'!J:J,'Aug25 Dep'!F:F,'Summary Rollforward'!$B10) -> 0 | CW10: =SUMIFS('Contract Data'!IS:IS,'Contract Data'!$C:$C,'Summary Rollforward'!$B10) -> 96875 | CY10: =+CP10+CU10+CV10 -> 0 | CZ10: =+DA10-CY10 -> 182812.5 | DA10: =+CR10+CT10+CV10+CU10 -> 182812.5 | DC10: =DF10-DD10 -> -59375 | DD10: =SUMIFS('Sep 25 Inv'!H:H,'Sep 25 Inv'!E:E,'Summary Rollforward'!$B10) -> 156250 | DE10: =-SUMIFS('Sep25 Dep'!J:J,'Sep25 Dep'!F:F,'Summary Rollforward'!$B10) -> -156250 | DF10: =SUMIFS('Contract Data'!IT:IT,'Contract Data'!$C:$C,'Summary Rollforward'!$B10) -> 96875 | DH10: =+CY10+DD10+DE10 -> 0 | DI10: =+DJ10-DH10 -> 123437.5 | DJ10: =+DA10+DC10+DE10+DD10 -> 123437.5 | DL10: =DO10-DM10 -> 40000 | DM10: =SUMIFS('Oct 25 Inv'!H:H,'Oct 25 Inv'!E:E,'Summary Rollforward'!$B10) -> 0 | DN10: =-SUMIFS('Oct25 Dep'!J:J,'Oct25 Dep'!F:F,'Summary Rollforward'!$B10) -> 0 | DO10: =SUMIFS('Contract Data'!IU:IU,'Contract Data'!$C:$C,'Summary Rollforward'!$B10) -> 40000 | DQ10: =+DH10+DM10+DN10 -> 0 | DR10: =+DS10-DQ10 -> 163437.5 | DS10: =+DJ10+DL10+DN10+DM10 -> 163437.5 | DU10: =DX10-DV10 -> 30000 | DV10: =SUMIFS('Nov 25 Inv'!H:H,'Nov 25 Inv'!E:E,'Summary Rollforward'!$B10) -> 0 | DW10: =-SUMIFS('Nov25 Dep'!J:J,'Nov25 Dep'!F:F,'Summary Rollforward'!$B10) -> 0 | DX10: =SUMIFS('Contract Data'!IV:IV,'Contract Data'!$C:$C,'Summary Rollforward'!$B10) -> 30000 | DZ10: =+DQ10+DV10+DW10 -> 0 | EA10: =+EB10-DZ10 -> 193437.5 | EB10: =+DS10+DU10+DW10+DV10 -> 193437.5 | ED10: =EG10-EE10 -> -126250 | EE10: =SUMIFS('Dec 25 Inv'!H:H,'Dec 25 Inv'!E:E,'Summary Rollforward'!$B10) -> 156250 | EF10: =-SUMIFS('Dec25 Dep'!I:I,'Dec25 Dep'!F:F,'Summary Rollforward'!$B10) -> 0 | EG10: =SUMIFS('Contract Data'!IW:IW,'Contract Data'!$C:$C,'Summary Rollforward'!$B10) -> 30000 | EI10: =+DZ10+EE10+EF10 -> 156250 | EJ10: =+EK10-EI10 -> 67187.5 | EK10: =+EB10+ED10+EF10+EE10 -> 223437.5
B11: Breg | C11: HPS Investment Partners | AD11: =+'AR Calculation - Service'!AQ273-AE11 -> 250843 | AJ11: =+AK11-AI11 -> 250843 | AK11: =+AB11+AD11+AG11+AF11+AE11 -> 250843 | AM11: 0 | AO11: =-'Oct Collections'!AF10-'Oct Collections'!AF11 -> 0 | AQ11: =+AI11+AN11+AO11 -> 0 | AR11: =+AS11-AQ11 -> 250843 | AS11: =+AK11+AM11+AO11+AN11 -> 250843 | AU11: 0 | AW11: =-'Oct Collections'!AN10-'Oct Collections'!AN11 -> 0 | AY11: =+AQ11+AV11+AW11 -> 0 | AZ11: =+BA11-AY11 -> 250843 | BA11: =+AS11+AU11+AW11+AV11 -> 250843 | BC11: 0 | BG11: =+AY11+BD11+BE11 -> 0 | BH11: =+BI11-BG11 -> 250843 | BI11: =+BA11+BC11+BE11+BD11 -> 250843 | BO11: =+BG11+BL11+BM11 -> 0 | BP11: =+BQ11-BO11 -> 250843 | BQ11: =+BI11+BK11+BM11+BL11 -> 250843 | BS11: =BV11-BT11 -> -62866 | BT11: 62866 | BU11: 0 | BV11: =SUMIFS('Contract Data'!IP:IP,'Contract Data'!C:C,'Summary Rollforward'!B11) -> 0 | BX11: =+BO11+BT11+BU11 -> 62866 | BY11: =+BZ11-BX11 -> 187977 | BZ11: =+BQ11+BS11+BU11+BT11 -> 250843 | CB11: =CE11-CC11 -> 38500 | CC11: =SUMIFS('June 25 Inv'!G:G,'June 25 Inv'!D:D,'Summary Rollforward'!$B11) -> 0 | CD11: =-SUMIFS('Jun25 Dep'!I:I,'Jun25 Dep'!F:F,'Summary Rollforward'!$B11) -> 0 | CE11: =SUMIFS('Contract Data'!IQ:IQ,'Contract Data'!$C:$C,'Summary Rollforward'!$B11) -> 38500 | CG11: =+BX11+CC11+CD11 -> 62866 | CH11: =+CI11-CG11 -> 226477 | CI11: =+BZ11+CB11+CD11+CC11 -> 289343 | CK11: =CN11-CL11 -> 0 | CL11: =SUMIFS('Jul 25 Inv'!H:H,'Jul 25 Inv'!E:E,'Summary Rollforward'!$B11) -> 0 | CM11: =-SUMIFS('Jul25 Dep'!J:J,'Jul25 Dep'!F:F,'Summary Rollforward'!$B11) -> 0 | CN11: =SUMIFS('Contract Data'!IR:IR,'Contract Data'!$C:$C,'Summary Rollforward'!$B11) -> 0 | CP11: =+CG11+CL11+CM11 -> 62866 | CQ11: =+CR11-CP11 -> 226477 | CR11: =+CI11+CK11+CM11+CL11 -> 289343 | CT11: =CW11-CU11 -> 20895 | CU11: =SUMIFS('Aug 25 Inv'!H:H,'Aug 25 Inv'!E:E,'Summary Rollforward'!$B11) -> 0 | CV11: =-SUMIFS('Aug25 Dep'!J:J,'Aug25 Dep'!F:F,'Summary Rollforward'!$B11) -> 0 | CW11: =SUMIFS('Contract Data'!IS:IS,'Contract Data'!$C:$C,'Summary Rollforward'!$B11) -> 20895 | CY11: =+CP11+CU11+CV11 -> 62866 | CZ11: =+DA11-CY11 -> 247372 | DA11: =+CR11+CT11+CV11+CU11 -> 310238 | DC11: =DF11-DD11 -> 30151.25 | DD11: =SUMIFS('Sep 25 Inv'!H:H,'Sep 25 Inv'!E:E,'Summary Rollforward'!$B11) -> 0 | DE11: =-SUMIFS('Sep25 Dep'!J:J,'Sep25 Dep'!F:F,'Summary Rollforward'!$B11) -> -62866 | DF11: =SUMIFS('Contract Data'!IT:IT,'Contract Data'!$C:$C,'Summary Rollforward'!$B11) -> 30151.25 | DH11: =+CY11+DD11+DE11 -> 0 | DI11: =+DJ11-DH11 -> 277523.25 | DJ11: =+DA11+DC11+DE11+DD11 -> 277523.25 | DL11: =DO11-DM11 -> 30151.25 | DM11: =SUMIFS('Oct 25 Inv'!H:H,'Oct 25 Inv'!E:E,'Summary Rollforward'!$B11) -> 0 | DN11: =-SUMIFS('Oct25 Dep'!J:J,'Oct25 Dep'!F:F,'Summary Rollforward'!$B11) -> 0 | DO11: =SUMIFS('Contract Data'!IU:IU,'Contract Data'!$C:$C,'Summary Rollforward'!$B11) -> 30151.25 | DQ11: =+DH11+DM11+DN11 -> 0 | DR11: =+DS11-DQ11 -> 307674.5 | DS11: =+DJ11+DL11+DN11+DM11 -> 307674.5 | DU11: =DX11-DV11 -> 50000 | DV11: =SUMIFS('Nov 25 Inv'!H:H,'Nov 25 Inv'!E:E,'Summary Rollforward'!$B11) -> 0 | DW11: =-SUMIFS('Nov25 Dep'!J:J,'Nov25 Dep'!F:F,'Summary Rollforward'!$B11) -> 0 | DX11: =SUMIFS('Contract Data'!IV:IV,'Contract Data'!$C:$C,'Summary Rollforward'!$B11) -> 50000 | DZ11: =+DQ11+DV11+DW11 -> 0 | EA11: =+EB11-DZ11 -> 357674.5 | EB11: =+DS11+DU11+DW11+DV11 -> 357674.5 | ED11: =EG11-EE11 -> 60000 | EE11: =SUMIFS('Dec 25 Inv'!H:H,'Dec 25 Inv'!E:E,'Summary Rollforward'!$B11) -> 0 | EF11: =-SUMIFS('Dec25 Dep'!I:I,'Dec25 Dep'!F:F,'Summary Rollforward'!$B11) -> 0 | EG11: =SUMIFS('Contract Data'!IW:IW,'Contract Data'!$C:$C,'Summary Rollforward'!$B11) -> 60000 | EI11: =+DZ11+EE11+EF11 -> 0 | EJ11: =+EK11-EI11 -> 417674.5 | EK11: =+EB11+ED11+EF11+EE11 -> 417674.5
B12: Bright Event Rentals | C12: Trivest | BS12: =BV12-BT12 -> -18375 | BT12: 30000 | BU12: 0 | BV12: =SUMIFS('Contract Data'!IP:IP,'Contract Data'!C:C,'Summary Rollforward'!B12) -> 11625 | BX12: =+BO12+BT12+BU12 -> 30000 | BY12: =+BZ12-BX12 -> -18375 | BZ12: =+BQ12+BS12+BU12+BT12 -> 11625 | CB12: =CE12-CC12 -> -6750 | CC12: =SUMIFS('June 25 Inv'!G:G,'June 25 Inv'!D:D,'Summary Rollforward'!$B12) -> 30000 | CD12: =-SUMIFS('Jun25 Dep'!I:I,'Jun25 Dep'!F:F,'Summary Rollforward'!$B12) -> 0 | CE12: =SUMIFS('Contract Data'!IQ:IQ,'Contract Data'!$C:$C,'Summary Rollforward'!$B12) -> 23250 | CG12: =+BX12+CC12+CD12 -> 60000 | CH12: =+CI12-CG12 -> -25125 | CI12: =+BZ12+CB12+CD12+CC12 -> 34875 | CK12: =CN12-CL12 -> -6750 | CL12: =SUMIFS('Jul 25 Inv'!H:H,'Jul 25 Inv'!E:E,'Summary Rollforward'!$B12) -> 30000 | CM12: =-SUMIFS('Jul25 Dep'!J:J,'Jul25 Dep'!F:F,'Summary Rollforward'!$B12) -> 0 | CN12: =SUMIFS('Contract Data'!IR:IR,'Contract Data'!$C:$C,'Summary Rollforward'!$B12) -> 23250 | CP12: =+CG12+CL12+CM12 -> 90000 | CQ12: =+CR12-CP12 -> -31875 | CR12: =+CI12+CK12+CM12+CL12 -> 58125 | CT12: =CW12-CU12 -> 24750 | CU12: =SUMIFS('Aug 25 Inv'!H:H,'Aug 25 Inv'!E:E,'Summary Rollforward'!$B12) -> 30000 | CV12: =-SUMIFS('Aug25 Dep'!J:J,'Aug25 Dep'!F:F,'Summary Rollforward'!$B12) -> -30000 | CW12: =SUMIFS('Contract Data'!IS:IS,'Contract Data'!$C:$C,'Summary Rollforward'!$B12) -> 54750 | CY12: =+CP12+CU12+CV12 -> 90000 | CZ12: =+DA12-CY12 -> -7125 | DA12: =+CR12+CT12+CV12+CU12 -> 82875 | DC12: =DF12-DD12 -> 59250 | DD12: =SUMIFS('Sep 25 Inv'!H:H,'Sep 25 Inv'!E:E,'Summary Rollforward'!$B12) -> 30000 | DE12: =-SUMIFS('Sep25 Dep'!J:J,'Sep25 Dep'!F:F,'Summary Rollforward'!$B12) -> -60000 | DF12: =SUMIFS('Contract Data'!IT:IT,'Contract Data'!$C:$C,'Summary Rollforward'!$B12) -> 89250 | DH12: =+CY12+DD12+DE12 -> 60000 | DI12: =+DJ12-DH12 -> 52125 | DJ12: =+DA12+DC12+DE12+DD12 -> 112125 | DL12: =DO12-DM12 -> 89250 | DM12: =SUMIFS('Oct 25 Inv'!H:H,'Oct 25 Inv'!E:E,'Summary Rollforward'!$B12) -> 0 | DN12: =-SUMIFS('Oct25 Dep'!J:J,'Oct25 Dep'!F:F,'Summary Rollforward'!$B12) -> -30000 | DO12: =SUMIFS('Contract Data'!IU:IU,'Contract Data'!$C:$C,'Summary Rollforward'!$B12) -> 89250 | DQ12: =+DH12+DM12+DN12 -> 30000 | DR12: =+DS12-DQ12 -> 141375 | DS12: =+DJ12+DL12+DN12+DM12 -> 171375 | DU12: =DX12-DV12 -> 71500 | DV12: =SUMIFS('Nov 25 Inv'!H:H,'Nov 25 Inv'!E:E,'Summary Rollforward'!$B12) -> 0 | DW12: =-SUMIFS('Nov25 Dep'!J:J,'Nov25 Dep'!F:F,'Summary Rollforward'!$B12) -> -30000 | DX12: =SUMIFS('Contract Data'!IV:IV,'Contract Data'!$C:$C,'Summary Rollforward'!$B12) -> 71500 | DZ12: =+DQ12+DV12+DW12 -> 0 | EA12: =+EB12-DZ12 -> 212875 | EB12: =+DS12+DU12+DW12+DV12 -> 212875 | ED12: =EG12-EE12 -> 71500 | EE12: =SUMIFS('Dec 25 Inv'!H:H,'Dec 25 Inv'!E:E,'Summary Rollforward'!$B12) -> 0 | EF12: =-SUMIFS('Dec25 Dep'!I:I,'Dec25 Dep'!F:F,'Summary Rollforward'!$B12) -> 0 | EG12: =SUMIFS('Contract Data'!IW:IW,'Contract Data'!$C:$C,'Summary Rollforward'!$B12) -> 71500 | EI12: =+DZ12+EE12+EF12 -> 0 | EJ12: =+EK12-EI12 -> 284375 | EK12: =+EB12+ED12+EF12+EE12 -> 284375
B13: Café Rio | C13: Freeman Spogoli | AD13: =+'AR Calculation - Service'!AQ36-AE13 -> 0 | AE13: =+'Dec Invoicing'!I8 -> 27530 | AI13: =+'Dec 31'!G7 -> 27530 | AJ13: =+AK13-AI13 -> 0 | AK13: =+AB13+AD13+AG13+AF13+AE13 -> 27530 | AM13: 0 | AN13: =+'Dec Invoicing'!Q8 -> 0 | AO13: =+'AR Calculation - Service'!AR35 -> -27530 | AQ13: =+AI13+AN13+AO13 -> 0 | AR13: =+AS13-AQ13 -> 0 | AS13: =+AK13+AM13+AO13+AN13 -> 0 | AU13: 0 | AV13: =+'Dec Invoicing'!Y8 -> 0 | AW13: 0 | AY13: =+AQ13+AV13+AW13 -> 0 | AZ13: =+BA13-AY13 -> 0 | BA13: =+AS13+AU13+AW13+AV13 -> 0 | BC13: 0 | BD13: =+'Dec Invoicing'!AG8 -> 0 | BG13: =+AY13+BD13+BE13 -> 0 | BH13: =+BI13-BG13 -> 0 | BI13: =+BA13+BC13+BE13+BD13 -> 0 | BK13: =+'AR Calculation - Service'!AU36-'Summary Rollforward'!BL13 -> 34673 | BL13: 0 | BO13: =+BG13+BL13+BM13 -> 0 | BP13: =+BQ13-BO13 -> 34673 | BQ13: =+BI13+BK13+BM13+BL13 -> 34673 | BS13: =BV13-BT13 -> -34673 | BT13: 34673 | BU13: 0 | BV13: =SUMIFS('Contract Data'!IP:IP,'Contract Data'!C:C,'Summary Rollforward'!B13) -> 0 | BX13: =+BO13+BT13+BU13 -> 34673 | BY13: =+BZ13-BX13 -> 0 | BZ13: =+BQ13+BS13+BU13+BT13 -> 34673 | CB13: =CE13-CC13 -> 0 | CC13: =SUMIFS('June 25 Inv'!G:G,'June 25 Inv'!D:D,'Summary Rollforward'!$B13) -> 0 | CD13: =-SUMIFS('Jun25 Dep'!I:I,'Jun25 Dep'!F:F,'Summary Rollforward'!$B13) -> -34673 | CE13: =SUMIFS('Contract Data'!IQ:IQ,'Contract Data'!$C:$C,'Summary Rollforward'!$B13) -> 0 | CG13: =+BX13+CC13+CD13 -> 0 | CH13: =+CI13-CG13 -> 0 | CI13: =+BZ13+CB13+CD13+CC13 -> 0 | CK13: =CN13-CL13 -> 0 | CL13: =SUMIFS('Jul 25 Inv'!H:H,'Jul 25 Inv'!E:E,'Summary Rollforward'!$B13) -> 0 | CM13: =-SUMIFS('Jul25 Dep'!J:J,'Jul25 Dep'!F:F,'Summary Rollforward'!$B13) -> 0 | CN13: =SUMIFS('Contract Data'!IR:IR,'Contract Data'!$C:$C,'Summary Rollforward'!$B13) -> 0 | CP13: =+CG13+CL13+CM13 -> 0 | CQ13: =+CR13-CP13 -> 0 | CR13: =+CI13+CK13+CM13+CL13 -> 0 | CT13: =CW13-CU13 -> 0 | CU13: =SUMIFS('Aug 25 Inv'!H:H,'Aug 25 Inv'!E:E,'Summary Rollforward'!$B13) -> 0 | CV13: =-SUMIFS('Aug25 Dep'!J:J,'Aug25 Dep'!F:F,'Summary Rollforward'!$B13) -> 0 | CW13: =SUMIFS('Contract Data'!IS:IS,'Contract Data'!$C:$C,'Summary Rollforward'!$B13) -> 0 | CY13: =+CP13+CU13+CV13 -> 0 | CZ13: =+DA13-CY13 -> 0 | DA13: =+CR13+CT13+CV13+CU13 -> 0 | DC13: =DF13-DD13 -> 0 | DD13: =SUMIFS('Sep 25 Inv'!H:H,'Sep 25 Inv'!E:E,'Summary Rollforward'!$B13) -> 0 | DE13: =-SUMIFS('Sep25 Dep'!J:J,'Sep25 Dep'!F:F,'Summary Rollforward'!$B13) -> 0 | DF13: =SUMIFS('Contract Data'!IT:IT,'Contract Data'!$C:$C,'Summary Rollforward'!$B13) -> 0 | DH13: =+CY13+DD13+DE13 -> 0 | DI13: =+DJ13-DH13 -> 0 | DJ13: =+DA13+DC13+DE13+DD13 -> 0 | DL13: =DO13-DM13 -> 0 | DM13: =SUMIFS('Oct 25 Inv'!H:H,'Oct 25 Inv'!E:E,'Summary Rollforward'!$B13) -> 0 | DN13: =-SUMIFS('Oct25 Dep'!J:J,'Oct25 Dep'!F:F,'Summary Rollforward'!$B13) -> 0 | DO13: =SUMIFS('Contract Data'!IU:IU,'Contract Data'!$C:$C,'Summary Rollforward'!$B13) -> 0 | DQ13: =+DH13+DM13+DN13 -> 0 | DR13: =+DS13-DQ13 -> 0 | DS13: =+DJ13+DL13+DN13+DM13 -> 0 | DU13: =DX13-DV13 -> 13215.333 | DV13: =SUMIFS('Nov 25 Inv'!H:H,'Nov 25 Inv'!E:E,'Summary Rollforward'!$B13) -> 0 | DW13: =-SUMIFS('Nov25 Dep'!J:J,'Nov25 Dep'!F:F,'Summary Rollforward'!$B13) -> 0 | DX13: =SUMIFS('Contract Data'!IV:IV,'Contract Data'!$C:$C,'Summary Rollforward'!$B13) -> 13215.333 | DZ13: =+DQ13+DV13+DW13 -> 0 | EA13: =+EB13-DZ13 -> 13215.333 | EB13: =+DS13+DU13+DW13+DV13 -> 13215.333 | ED13: =EG13-EE13 -> 0 | EE13: =SUMIFS('Dec 25 Inv'!H:H,'Dec 25 Inv'!E:E,'Summary Rollforward'!$B13) -> 0 | EF13: =-SUMIFS('Dec25 Dep'!I:I,'Dec25 Dep'!F:F,'Summary Rollforward'!$B13) -> 0 | EG13: =SUMIFS('Contract Data'!IW:IW,'Contract Data'!$C:$C,'Summary Rollforward'!$B13) -> 0 | EI13: =+DZ13+EE13+EF13 -> 0 | EJ13: =+EK13-EI13 -> 13215.333 | EK13: =+EB13+ED13+EF13+EE13 -> 13215.333
B14: California Fish Grill | C14: KarpReilly | CB14: =CE14-CC14 -> -1545.83 | CC14: =SUMIFS('June 25 Inv'!G:G,'June 25 Inv'!D:D,'Summary Rollforward'!$B14) -> 22083.33 | CD14: =-SUMIFS('Jun25 Dep'!I:I,'Jun25 Dep'!F:F,'Summary Rollforward'!$B14) -> 0 | CE14: =SUMIFS('Contract Data'!IQ:IQ,'Contract Data'!$C:$C,'Summary Rollforward'!$B14) -> 20537.5 | CG14: =+BX14+CC14+CD14 -> 22083.33 | CH14: =+CI14-CG14 -> -1545.83 | CI14: =+BZ14+CB14+CD14+CC14 -> 20537.5 | CK14: =CN14-CL14 -> 18991.67 | CL14: =SUMIFS('Jul 25 Inv'!H:H,'Jul 25 Inv'!E:E,'Summary Rollforward'!$B14) -> 22083.33 | CM14: =-SUMIFS('Jul25 Dep'!J:J,'Jul25 Dep'!F:F,'Summary Rollforward'!$B14) -> 0 | CN14: =SUMIFS('Contract Data'!IR:IR,'Contract Data'!$C:$C,'Summary Rollforward'!$B14) -> 41075 | CP14: =+CG14+CL14+CM14 -> 44166.66 | CQ14: =+CR14-CP14 -> 17445.84 | CR14: =+CI14+CK14+CM14+CL14 -> 61612.5 | CT14: =CW14-CU14 -> 18991.67 | CU14: =SUMIFS('Aug 25 Inv'!H:H,'Aug 25 Inv'!E:E,'Summary Rollforward'!$B14) -> 22083.33 | CV14: =-SUMIFS('Aug25 Dep'!J:J,'Aug25 Dep'!F:F,'Summary Rollforward'!$B14) -> -22083.33 | CW14: =SUMIFS('Contract Data'!IS:IS,'Contract Data'!$C:$C,'Summary Rollforward'!$B14) -> 41075 | CY14: =+CP14+CU14+CV14 -> 44166.66 | CZ14: =+DA14-CY14 -> 36437.51 | DA14: =+CR14+CT14+CV14+CU14 -> 80604.17 | DC14: =DF14-DD14 -> 35220.72 | DD14: =SUMIFS('Sep 25 Inv'!H:H,'Sep 25 Inv'!E:E,'Summary Rollforward'!$B14) -> 22083.33 | DE14: =-SUMIFS('Sep25 Dep'!J:J,'Sep25 Dep'!F:F,'Summary Rollforward'!$B14) -> -44166.66 | DF14: =SUMIFS('Contract Data'!IT:IT,'Contract Data'!$C:$C,'Summary Rollforward'!$B14) -> 57304.05 | DH14: =+CY14+DD14+DE14 -> 22083.33 | DI14: =+DJ14-DH14 -> 71658.23 | DJ14: =+DA14+DC14+DE14+DD14 -> 93741.56 | DL14: =DO14-DM14 -> 51449.77 | DM14: =SUMIFS('Oct 25 Inv'!H:H,'Oct 25 Inv'!E:E,'Summary Rollforward'!$B14) -> 22083.33 | DN14: =-SUMIFS('Oct25 Dep'!J:J,'Oct25 Dep'!F:F,'Summary Rollforward'!$B14) -> -22083.33 | DO14: =SUMIFS('Contract Data'!IU:IU,'Contract Data'!$C:$C,'Summary Rollforward'!$B14) -> 73533.1 | DQ14: =+DH14+DM14+DN14 -> 22083.33 | DR14: =+DS14-DQ14 -> 123108 | DS14: =+DJ14+DL14+DN14+DM14 -> 145191.33 | DU14: =DX14-DV14 -> 22916.67 | DV14: =SUMIFS('Nov 25 Inv'!H:H,'Nov 25 Inv'!E:E,'Summary Rollforward'!$B14) -> 22083.33 | DW14: =-SUMIFS('Nov25 Dep'!J:J,'Nov25 Dep'!F:F,'Summary Rollforward'!$B14) -> 0 | DX14: =SUMIFS('Contract Data'!IV:IV,'Contract Data'!$C:$C,'Summary Rollforward'!$B14) -> 45000 | DZ14: =+DQ14+DV14+DW14 -> 44166.66 | EA14: =+EB14-DZ14 -> 146024.67 | EB14: =+DS14+DU14+DW14+DV14 -> 190191.33 | ED14: =EG14-EE14 -> 7916.67 | EE14: =SUMIFS('Dec 25 Inv'!H:H,'Dec 25 Inv'!E:E,'Summary Rollforward'!$B14) -> 24197.49 | EF14: =-SUMIFS('Dec25 Dep'!I:I,'Dec25 Dep'!F:F,'Summary Rollforward'!$B14) -> -44166.66 | EG14: =SUMIFS('Contract Data'!IW:IW,'Contract Data'!$C:$C,'Summary Rollforward'!$B14) -> 32114.16 | EI14: =+DZ14+EE14+EF14 -> 24197.49 | EJ14: =+EK14-EI14 -> 153941.34 | EK14: =+EB14+ED14+EF14+EE14 -> 178138.83
B15: CAM | C15: Cross Rapids | E15: 0 | F15: =+G15-E15 -> 57750 | G15: =+'AR Calculation - Service'!AM41 -> 57750 | I15: =+'AR Calculation - Service'!AN40 -> 59675 | M15: =+N15-L15 -> 117425 | N15: =+G15+I15+J15 -> 117425 | P15: 36575 | S15: =+'Oct 31'!G7 -> 77000 | T15: =+U15-S15 -> 77000 | U15: =+N15+P15+Q15 -> 154000 | W15: 0 | X15: =+'Nov Collections'!I59 -> -77000 | Z15: =+'Nov 30'!G7 -> 77000 | AA15: =+AB15-Z15 -> 0 | AB15: =+U15+W15+X15 -> 77000 | AD15: 0 | AG15: ='AR Calculation - Service'!AQ39 -> -77000 | AI15: =+'Nov 30'!K7 -> 0 | AJ15: =+AK15-AI15 -> -2.910383e-11 | AK15: =+AB15+AD15+AG15+AF15+AE15 -> -2.910383e-11 | AM15: 0 | AO15: =-'Oct Collections'!AF12-'Oct Collections'!AF13 -> 0 | AQ15: =+AI15+AN15+AO15 -> 0 | AR15: =+AS15-AQ15 -> -2.910383e-11 | AS15: =+AK15+AM15+AO15+AN15 -> -2.910383e-11 | AU15: 0 | AW15: =-'Oct Collections'!AN12-'Oct Collections'!AN13 -> 0 | AY15: =+AQ15+AV15+AW15 -> 0 | AZ15: =+BA15-AY15 -> -2.910383e-11 | BA15: =+AS15+AU15+AW15+AV15 -> -2.910383e-11 | BC15: 0 | BG15: =+AY15+BD15+BE15 -> 0 | BH15: =+BI15-BG15 -> -2.910383e-11 | BI15: =+BA15+BC15+BE15+BD15 -> -2.910383e-11 | BO15: =+BG15+BL15+BM15 -> 0 | BP15: =+BQ15-BO15 -> -2.910383e-11 | BQ15: =+BI15+BK15+BM15+BL15 -> -2.910383e-11 | BS15: =BV15-BT15 -> 0 | BT15: 0 | BU15: 0 | BV15: =SUMIFS('Contract Data'!IP:IP,'Contract Data'!C:C,'Summary Rollforward'!B15) -> 0 | BX15: =+BO15+BT15+BU15 -> 0 | BY15: =+BZ15-BX15 -> -2.910383e-11 | BZ15: =+BQ15+BS15+BU15+BT15 -> -2.910383e-11 | CB15: =CE15-CC15 -> 0 | CC15: =SUMIFS('June 25 Inv'!G:G,'June 25 Inv'!D:D,'Summary Rollforward'!$B15) -> 0 | CD15: =-SUMIFS('Jun25 Dep'!I:I,'Jun25 Dep'!F:F,'Summary Rollforward'!$B15) -> 0 | CE15: =SUMIFS('Contract Data'!IQ:IQ,'Contract Data'!$C:$C,'Summary Rollforward'!$B15) -> 0 | CG15: =+BX15+CC15+CD15 -> 0 | CH15: =+CI15-CG15 -> -2.910383e-11 | CI15: =+BZ15+CB15+CD15+CC15 -> -2.910383e-11 | CK15: =CN15-CL15 -> 0 | CL15: =SUMIFS('Jul 25 Inv'!H:H,'Jul 25 Inv'!E:E,'Summary Rollforward'!$B15) -> 0 | CM15: =-SUMIFS('Jul25 Dep'!J:J,'Jul25 Dep'!F:F,'Summary Rollforward'!$B15) -> 0 | CN15: =SUMIFS('Contract Data'!IR:IR,'Contract Data'!$C:$C,'Summary Rollforward'!$B15) -> 0 | CP15: =+CG15+CL15+CM15 -> 0 | CQ15: =+CR15-CP15 -> -2.910383e-11 | CR15: =+CI15+CK15+CM15+CL15 -> -2.910383e-11 | CT15: =CW15-CU15 -> 0 | CU15: =SUMIFS('Aug 25 Inv'!H:H,'Aug 25 Inv'!E:E,'Summary Rollforward'!$B15) -> 0 | CV15: =-SUMIFS('Aug25 Dep'!J:J,'Aug25 Dep'!F:F,'Summary Rollforward'!$B15) -> 0 | CW15: =SUMIFS('Contract Data'!IS:IS,'Contract Data'!$C:$C,'Summary Rollforward'!$B15) -> 0 | CY15: =+CP15+CU15+CV15 -> 0 | CZ15: =+DA15-CY15 -> -2.910383e-11 | DA15: =+CR15+CT15+CV15+CU15 -> -2.910383e-11 | DC15: =DF15-DD15 -> 0 | DD15: =SUMIFS('Sep 25 Inv'!H:H,'Sep 25 Inv'!E:E,'Summary Rollforward'!$B15) -> 0 | DE15: =-SUMIFS('Sep25 Dep'!J:J,'Sep25 Dep'!F:F,'Summary Rollforward'!$B15) -> 0 | DF15: =SUMIFS('Contract Data'!IT:IT,'Contract Data'!$C:$C,'Summary Rollforward'!$B15) -> 0 | DH15: =+CY15+DD15+DE15 -> 0 | DI15: =+DJ15-DH15 -> -2.910383e-11 | DJ15: =+DA15+DC15+DE15+DD15 -> -2.910383e-11 | DL15: =DO15-DM15 -> 0 | DM15: =SUMIFS('Oct 25 Inv'!H:H,'Oct 25 Inv'!E:E,'Summary Rollforward'!$B15) -> 0 | DN15: =-SUMIFS('Oct25 Dep'!J:J,'Oct25 Dep'!F:F,'Summary Rollforward'!$B15) -> 0 | DO15: =SUMIFS('Contract Data'!IU:IU,'Contract Data'!$C:$C,'Summary Rollforward'!$B15) -> 0 | DQ15: =+DH15+DM15+DN15 -> 0 | DR15: =+DS15-DQ15 -> -2.910383e-11 | DS15: =+DJ15+DL15+DN15+DM15 -> -2.910383e-11 | DU15: =DX15-DV15 -> 0 | DV15: =SUMIFS('Nov 25 Inv'!H:H,'Nov 25 Inv'!E:E,'Summary Rollforward'!$B15) -> 0 | DW15: =-SUMIFS('Nov25 Dep'!J:J,'Nov25 Dep'!F:F,'Summary Rollforward'!$B15) -> 0 | DX15: =SUMIFS('Contract Data'!IV:IV,'Contract Data'!$C:$C,'Summary Rollforward'!$B15) -> 0 | DZ15: =+DQ15+DV15+DW15 -> 0 | EA15: =+EB15-DZ15 -> -2.910383e-11 | EB15: =+DS15+DU15+DW15+DV15 -> -2.910383e-11 | ED15: =EG15-EE15 -> 2.910383e-11 | EE15: =SUMIFS('Dec 25 Inv'!H:H,'Dec 25 Inv'!E:E,'Summary Rollforward'!$B15) -> 0 | EF15: =-SUMIFS('Dec25 Dep'!I:I,'Dec25 Dep'!F:F,'Summary Rollforward'!$B15) -> 0 | EG15: =-EB15 -> 2.910383e-11 | EI15: =+DZ15+EE15+EF15 -> 0 | EJ15: =+EK15-EI15 -> 0 | EK15: =+EB15+ED15+EF15+EE15 -> 0
B16: Capsa Healthcare | C16: LLCP | ED16: =EG16-EE16 -> 0 | EE16: =SUMIFS('Dec 25 Inv'!H:H,'Dec 25 Inv'!E:E,'Summary Rollforward'!$B16) -> 30000 | EF16: =-SUMIFS('Dec25 Dep'!I:I,'Dec25 Dep'!F:F,'Summary Rollforward'!$B16) -> 0 | EG16: =SUMIFS('Contract Data'!IW:IW,'Contract Data'!$C:$C,'Summary Rollforward'!$B16) -> 30000 | EI16: =+DZ16+EE16+EF16 -> 30000 | EJ16: =+EK16-EI16 -> 0 | EK16: =+EB16+ED16+EF16+EE16 -> 30000
B17: Cascade | C17: Trive | BK17: =+'AR Calculation - Service'!AU381-'Summary Rollforward'!BL17 -> 65875 | BL17: 0 | BO17: =+BG17+BL17+BM17 -> 0 | BP17: =+BQ17-BO17 -> 65875 | BQ17: =+BI17+BK17+BM17+BL17 -> 65875 | BS17: =BV17-BT17 -> 65875 | BT17: 0 | BU17: 0 | BV17: =SUMIFS('Contract Data'!IP:IP,'Contract Data'!C:C,'Summary Rollforward'!B17) -> 65875 | BX17: =+BO17+BT17+BU17 -> 0 | BY17: =+BZ17-BX17 -> 131750 | BZ17: =+BQ17+BS17+BU17+BT17 -> 131750 | CB17: =CE17-CC17 -> 65875 | CC17: =SUMIFS('June 25 Inv'!G:G,'June 25 Inv'!D:D,'Summary Rollforward'!$B17) -> 0 | CD17: =-SUMIFS('Jun25 Dep'!I:I,'Jun25 Dep'!F:F,'Summary Rollforward'!$B17) -> 0 | CE17: =SUMIFS('Contract Data'!IQ:IQ,'Contract Data'!$C:$C,'Summary Rollforward'!$B17) -> 65875 | CG17: =+BX17+CC17+CD17 -> 0 | CH17: =+CI17-CG17 -> 197625 | CI17: =+BZ17+CB17+CD17+CC17 -> 197625 | CK17: =CN17-CL17 -> 65875 | CL17: =SUMIFS('Jul 25 Inv'!H:H,'Jul 25 Inv'!E:E,'Summary Rollforward'!$B17) -> 0 | CM17: =-SUMIFS('Jul25 Dep'!J:J,'Jul25 Dep'!F:F,'Summary Rollforward'!$B17) -> 0 | CN17: =SUMIFS('Contract Data'!IR:IR,'Contract Data'!$C:$C,'Summary Rollforward'!$B17) -> 65875 | CP17: =+CG17+CL17+CM17 -> 0 | CQ17: =+CR17-CP17 -> 263500 | CR17: =+CI17+CK17+CM17+CL17 -> 263500 | CT17: =CW17-CU17 -> 65875 | CU17: =SUMIFS('Aug 25 Inv'!H:H,'Aug 25 Inv'!E:E,'Summary Rollforward'!$B17) -> 0 | CV17: =-SUMIFS('Aug25 Dep'!J:J,'Aug25 Dep'!F:F,'Summary Rollforward'!$B17) -> 0 | CW17: =SUMIFS('Contract Data'!IS:IS,'Contract Data'!$C:$C,'Summary Rollforward'!$B17) -> 65875 | CY17: =+CP17+CU17+CV17 -> 0 | CZ17: =+DA17-CY17 -> 329375 | DA17: =+CR17+CT17+CV17+CU17 -> 329375 | DC17: =DF17-DD17 -> -53125 | DD17: =SUMIFS('Sep 25 Inv'!H:H,'Sep 25 Inv'!E:E,'Summary Rollforward'!$B17) -> 85000 | DE17: =-SUMIFS('Sep25 Dep'!J:J,'Sep25 Dep'!F:F,'Summary Rollforward'!$B17) -> 0 | DF17: =SUMIFS('Contract Data'!IT:IT,'Contract Data'!$C:$C,'Summary Rollforward'!$B17) -> 31875 | DH17: =+CY17+DD17+DE17 -> 85000 | DI17: =+DJ17-DH17 -> 276250 | DJ17: =+DA17+DC17+DE17+DD17 -> 361250 | DL17: =DO17-DM17 -> -53125 | DM17: =SUMIFS('Oct 25 Inv'!H:H,'Oct 25 Inv'!E:E,'Summary Rollforward'!$B17) -> 85000 | DN17: =-SUMIFS('Oct25 Dep'!J:J,'Oct25 Dep'!F:F,'Summary Rollforward'!$B17) -> -85000 | DO17: =SUMIFS('Contract Data'!IU:IU,'Contract Data'!$C:$C,'Summary Rollforward'!$B17) -> 31875 | DQ17: =+DH17+DM17+DN17 -> 85000 | DR17: =+DS17-DQ17 -> 223125 | DS17: =+DJ17+DL17+DN17+DM17 -> 308125 | DU17: =DX17-DV17 -> -53125 | DV17: =SUMIFS('Nov 25 Inv'!H:H,'Nov 25 Inv'!E:E,'Summary Rollforward'!$B17) -> 85000 | DW17: =-SUMIFS('Nov25 Dep'!J:J,'Nov25 Dep'!F:F,'Summary Rollforward'!$B17) -> -85000 | DX17: =SUMIFS('Contract Data'!IV:IV,'Contract Data'!$C:$C,'Summary Rollforward'!$B17) -> 31875 | DZ17: =+DQ17+DV17+DW17 -> 85000 | EA17: =+EB17-DZ17 -> 170000 | EB17: =+DS17+DU17+DW17+DV17 -> 255000 | ED17: =EG17-EE17 -> 0 | EE17: =SUMIFS('Dec 25 Inv'!H:H,'Dec 25 Inv'!E:E,'Summary Rollforward'!$B17) -> 0 | EF17: =-SUMIFS('Dec25 Dep'!I:I,'Dec25 Dep'!F:F,'Summary Rollforward'!$B17) -> -85000 | EG17: =SUMIFS('Contract Data'!IW:IW,'Contract Data'!$C:$C,'Summary Rollforward'!$B17) -> 0 | EI17: =+DZ17+EE17+EF17 -> 0 | EJ17: =+EK17-EI17 -> 170000 | EK17: =+EB17+ED17+EF17+EE17 -> 170000
B18: Christianbook, LLC | C18: Nonantum Capital Partners | F18: =+G18-E18 -> 31250 | G18: =+'AR Calculation - Service'!AM286 -> 31250 | I18: =+'AR Calculation - Service'!AN285 -> 58125 | L18: =+'Sep 30'!G8 -> 75000 | M18: =+N18-L18 -> 14375 | N18: =+G18+I18+J18 -> 89375 | P18: 58125 | S18: =+'Oct 31'!G8 -> 150000 | T18: =+U18-S18 -> -2500 | U18: =+N18+P18+Q18 -> 147500 | W18: =+'AR Calculation - Service'!AP285 -> 58125 | X18: =+'Nov Collections'!I9+'Nov Collections'!I24 -> -150000 | Z18: =+'Nov 30'!G8 -> 75000 | AA18: =+AB18-Z18 -> -19375 | AB18: =+U18+W18+X18 -> 55625 | AD18: =+'AR Calculation - Service'!AQ285-AE18 -> 625 | AE18: =+'Dec Invoicing'!I9 -> 75000 | AG18: =+'AR Calculation - Service'!AQ284 -> -75000 | AI18: =+'Dec 31'!G8 -> 75000 | AJ18: =+AK18-AI18 -> -18750 | AK18: =+AB18+AD18+AG18+AF18+AE18 -> 56250 | AM18: =+'AR Calculation - Service'!AR285-'Summary Rollforward'!AN18 -> -12500 | AN18: =+'Jan Invoicing'!G7 -> 75000 | AO18: =+'AR Calculation - Service'!AR284 -> -75000 | AQ18: =+AI18+AN18+AO18 -> 75000 | AR18: =+AS18-AQ18 -> -31250 | AS18: =+AK18+AM18+AO18+AN18 -> 43750 | AU18: =+'AR Calculation - Service'!AS285-'Summary Rollforward'!AV18 -> 31250 | AV18: =+'Jan Invoicing'!O7 -> 0 | AW18: =+'AR Calculation - Service'!BB284 -> 0 | AY18: =+AQ18+AV18+AW18 -> 75000 | AZ18: =+BA18-AY18 -> 0 | BA18: =+AS18+AU18+AW18+AV18 -> 75000 | BC18: 0 | BD18: =+'Jan Invoicing'!W7 -> 0 | BE18: =+'AR Calculation - Service'!AT284 -> -75000 | BG18: =+AY18+BD18+BE18 -> 0 | BH18: =+BI18-BG18 -> 0 | BI18: =+BA18+BC18+BE18+BD18 -> 0 | BM18: =+'AR Calculation - Service'!BB284 -> 0 | BO18: =+BG18+BL18+BM18 -> 0 | BP18: =+BQ18-BO18 -> 0 | BQ18: =+BI18+BK18+BM18+BL18 -> 0 | BS18: =BV18-BT18 -> 0 | BT18: 0 | BU18: 0 | BV18: =SUMIFS('Contract Data'!IP:IP,'Contract Data'!C:C,'Summary Rollforward'!B18) -> 0 | BX18: =+BO18+BT18+BU18 -> 0 | BY18: =+BZ18-BX18 -> 0 | BZ18: =+BQ18+BS18+BU18+BT18 -> 0 | CB18: =CE18-CC18 -> 0 | CC18: =SUMIFS('June 25 Inv'!G:G,'June 25 Inv'!D:D,'Summary Rollforward'!$B18) -> 0 | CD18: =-SUMIFS('Jun25 Dep'!I:I,'Jun25 Dep'!F:F,'Summary Rollforward'!$B18) -> 0 | CE18: =SUMIFS('Contract Data'!IQ:IQ,'Contract Data'!$C:$C,'Summary Rollforward'!$B18) -> 0 | CG18: =+BX18+CC18+CD18 -> 0 | CH18: =+CI18-CG18 -> 0 | CI18: =+BZ18+CB18+CD18+CC18 -> 0 | CK18: =CN18-CL18 -> 0 | CL18: =SUMIFS('Jul 25 Inv'!H:H,'Jul 25 Inv'!E:E,'Summary Rollforward'!$B18) -> 0 | CM18: =-SUMIFS('Jul25 Dep'!J:J,'Jul25 Dep'!F:F,'Summary Rollforward'!$B18) -> 0 | CN18: =SUMIFS('Contract Data'!IR:IR,'Contract Data'!$C:$C,'Summary Rollforward'!$B18) -> 0 | CP18: =+CG18+CL18+CM18 -> 0 | CQ18: =+CR18-CP18 -> 0 | CR18: =+CI18+CK18+CM18+CL18 -> 0 | CT18: =CW18-CU18 -> 0 | CU18: =SUMIFS('Aug 25 Inv'!H:H,'Aug 25 Inv'!E:E,'Summary Rollforward'!$B18) -> 0 | CV18: =-SUMIFS('Aug25 Dep'!J:J,'Aug25 Dep'!F:F,'Summary Rollforward'!$B18) -> 0 | CW18: =SUMIFS('Contract Data'!IS:IS,'Contract Data'!$C:$C,'Summary Rollforward'!$B18) -> 0 | CY18: =+CP18+CU18+CV18 -> 0 | CZ18: =+DA18-CY18 -> 0 | DA18: =+CR18+CT18+CV18+CU18 -> 0 | DC18: =DF18-DD18 -> 0 | DD18: =SUMIFS('Sep 25 Inv'!H:H,'Sep 25 Inv'!E:E,'Summary Rollforward'!$B18) -> 0 | DE18: =-SUMIFS('Sep25 Dep'!J:J,'Sep25 Dep'!F:F,'Summary Rollforward'!$B18) -> 0 | DF18: =SUMIFS('Contract Data'!IT:IT,'Contract Data'!$C:$C,'Summary Rollforward'!$B18) -> 0 | DH18: =+CY18+DD18+DE18 -> 0 | DI18: =+DJ18-DH18 -> 0 | DJ18: =+DA18+DC18+DE18+DD18 -> 0 | DL18: =DO18-DM18 -> 0 | DM18: =SUMIFS('Oct 25 Inv'!H:H,'Oct 25 Inv'!E:E,'Summary Rollforward'!$B18) -> 0 | DN18: =-SUMIFS('Oct25 Dep'!J:J,'Oct25 Dep'!F:F,'Summary Rollforward'!$B18) -> 0 | DO18: =SUMIFS('Contract Data'!IU:IU,'Contract Data'!$C:$C,'Summary Rollforward'!$B18) -> 0 | DQ18: =+DH18+DM18+DN18 -> 0 | DR18: =+DS18-DQ18 -> 0 | DS18: =+DJ18+DL18+DN18+DM18 -> 0 | DU18: =DX18-DV18 -> 0 | DV18: =SUMIFS('Nov 25 Inv'!H:H,'Nov 25 Inv'!E:E,'Summary Rollforward'!$B18) -> 0 | DW18: =-SUMIFS('Nov25 Dep'!J:J,'Nov25 Dep'!F:F,'Summary Rollforward'!$B18) -> 0 | DX18: =SUMIFS('Contract Data'!IV:IV,'Contract Data'!$C:$C,'Summary Rollforward'!$B18) -> 0 | DZ18: =+DQ18+DV18+DW18 -> 0 | EA18: =+EB18-DZ18 -> 0 | EB18: =+DS18+DU18+DW18+DV18 -> 0 | ED18: =EG18-EE18 -> 0 | EE18: =SUMIFS('Dec 25 Inv'!H:H,'Dec 25 Inv'!E:E,'Summary Rollforward'!$B18) -> 0 | EF18: =-SUMIFS('Dec25 Dep'!I:I,'Dec25 Dep'!F:F,'Summary Rollforward'!$B18) -> 0 | EG18: =SUMIFS('Contract Data'!IW:IW,'Contract Data'!$C:$C,'Summary Rollforward'!$B18) -> 0 | EI18: =+DZ18+EE18+EF18 -> 0 | EJ18: =+EK18-EI18 -> 0 | EK18: =+EB18+ED18+EF18+EE18 -> 0
B19: Covercraft | C19: Century Park | E19: 0 | F19: =+G19-E19 -> 58367 | G19: =+'AR Calculation - Service'!AM57 -> 58367 | M19: =+N19-L19 -> 58367 | N19: =+G19+I19+J19 -> 58367 | S19: 0 | T19: =+U19-S19 -> 58367 | U19: =+N19+P19+Q19 -> 58367 | W19: 0 | Z19: 0 | AA19: =+AB19-Z19 -> 58367 | AB19: =+U19+W19+X19 -> 58367 | AD19: 0 | AF19: -58367 | AI19: 0 | AJ19: =+AK19-AI19 -> -1.1641532e-10 | AK19: =+AB19+AD19+AG19+AF19+AE19 -> -1.1641532e-10 | AM19: 0 | AO19: =-'Oct Collections'!AF14-'Oct Collections'!AF15 -> 0 | AQ19: =+AI19+AN19+AO19 -> 0 | AR19: =+AS19-AQ19 -> -1.1641532e-10 | AS19: =+AK19+AM19+AO19+AN19 -> -1.1641532e-10 | AU19: 0 | AW19: =-'Oct Collections'!AN14-'Oct Collections'!AN15 -> 0 | AY19: =+AQ19+AV19+AW19 -> 0 | AZ19: =+BA19-AY19 -> -1.1641532e-10 | BA19: =+AS19+AU19+AW19+AV19 -> -1.1641532e-10 | BC19: 0 | BG19: =+AY19+BD19+BE19 -> 0 | BH19: =+BI19-BG19 -> -1.1641532e-10 | BI19: =+BA19+BC19+BE19+BD19 -> -1.1641532e-10 | BO19: =+BG19+BL19+BM19 -> 0 | BP19: =+BQ19-BO19 -> -1.1641532e-10 | BQ19: =+BI19+BK19+BM19+BL19 -> -1.1641532e-10 | BS19: =BV19-BT19 -> 0 | BT19: 0 | BU19: 0 | BV19: =SUMIFS('Contract Data'!IP:IP,'Contract Data'!C:C,'Summary Rollforward'!B19) -> 0 | BX19: =+BO19+BT19+BU19 -> 0 | BY19: =+BZ19-BX19 -> -1.1641532e-10 | BZ19: =+BQ19+BS19+BU19+BT19 -> -1.1641532e-10 | CB19: =CE19-CC19 -> 0 | CC19: =SUMIFS('June 25 Inv'!G:G,'June 25 Inv'!D:D,'Summary Rollforward'!$B19) -> 0 | CD19: =-SUMIFS('Jun25 Dep'!I:I,'Jun25 Dep'!F:F,'Summary Rollforward'!$B19) -> 0 | CE19: =SUMIFS('Contract Data'!IQ:IQ,'Contract Data'!$C:$C,'Summary Rollforward'!$B19) -> 0 | CG19: =+BX19+CC19+CD19 -> 0 | CH19: =+CI19-CG19 -> -1.1641532e-10 | CI19: =+BZ19+CB19+CD19+CC19 -> -1.1641532e-10 | CK19: =CN19-CL19 -> 0 | CL19: =SUMIFS('Jul 25 Inv'!H:H,'Jul 25 Inv'!E:E,'Summary Rollforward'!$B19) -> 0 | CM19: =-SUMIFS('Jul25 Dep'!J:J,'Jul25 Dep'!F:F,'Summary Rollforward'!$B19) -> 0 | CN19: =SUMIFS('Contract Data'!IR:IR,'Contract Data'!$C:$C,'Summary Rollforward'!$B19) -> 0 | CP19: =+CG19+CL19+CM19 -> 0 | CQ19: =+CR19-CP19 -> -1.1641532e-10 | CR19: =+CI19+CK19+CM19+CL19 -> -1.1641532e-10 | CT19: =CW19-CU19 -> 0 | CU19: =SUMIFS('Aug 25 Inv'!H:H,'Aug 25 Inv'!E:E,'Summary Rollforward'!$B19) -> 0 | CV19: =-SUMIFS('Aug25 Dep'!J:J,'Aug25 Dep'!F:F,'Summary Rollforward'!$B19) -> 0 | CW19: =SUMIFS('Contract Data'!IS:IS,'Contract Data'!$C:$C,'Summary Rollforward'!$B19) -> 0 | CY19: =+CP19+CU19+CV19 -> 0 | CZ19: =+DA19-CY19 -> -1.1641532e-10 | DA19: =+CR19+CT19+CV19+CU19 -> -1.1641532e-10 | DC19: =DF19-DD19 -> 0 | DD19: =SUMIFS('Sep 25 Inv'!H:H,'Sep 25 Inv'!E:E,'Summary Rollforward'!$B19) -> 0 | DE19: =-SUMIFS('Sep25 Dep'!J:J,'Sep25 Dep'!F:F,'Summary Rollforward'!$B19) -> 0 | DF19: =SUMIFS('Contract Data'!IT:IT,'Contract Data'!$C:$C,'Summary Rollforward'!$B19) -> 0 | DH19: =+CY19+DD19+DE19 -> 0 | DI19: =+DJ19-DH19 -> -1.1641532e-10 | DJ19: =+DA19+DC19+DE19+DD19 -> -1.1641532e-10 | DL19: =DO19-DM19 -> 0 | DM19: =SUMIFS('Oct 25 Inv'!H:H,'Oct 25 Inv'!E:E,'Summary Rollforward'!$B19) -> 0 | DN19: =-SUMIFS('Oct25 Dep'!J:J,'Oct25 Dep'!F:F,'Summary Rollforward'!$B19) -> 0 | DO19: =SUMIFS('Contract Data'!IU:IU,'Contract Data'!$C:$C,'Summary Rollforward'!$B19) -> 0 | DQ19: =+DH19+DM19+DN19 -> 0 | DR19: =+DS19-DQ19 -> -1.1641532e-10 | DS19: =+DJ19+DL19+DN19+DM19 -> -1.1641532e-10 | DU19: =DX19-DV19 -> 0 | DV19: =SUMIFS('Nov 25 Inv'!H:H,'Nov 25 Inv'!E:E,'Summary Rollforward'!$B19) -> 0 | DW19: =-SUMIFS('Nov25 Dep'!J:J,'Nov25 Dep'!F:F,'Summary Rollforward'!$B19) -> 0 | DX19: =SUMIFS('Contract Data'!IV:IV,'Contract Data'!$C:$C,'Summary Rollforward'!$B19) -> 0 | DZ19: =+DQ19+DV19+DW19 -> 0 | EA19: =+EB19-DZ19 -> -1.1641532e-10 | EB19: =+DS19+DU19+DW19+DV19 -> -1.1641532e-10 | ED19: =EG19-EE19 -> 1.1641532e-10 | EE19: =SUMIFS('Dec 25 Inv'!H:H,'Dec 25 Inv'!E:E,'Summary Rollforward'!$B19) -> 0 | EF19: =-SUMIFS('Dec25 Dep'!I:I,'Dec25 Dep'!F:F,'Summary Rollforward'!$B19) -> 0 | EG19: =-EB19 -> 1.1641532e-10 | EI19: =+DZ19+EE19+EF19 -> 0 | EJ19: =+EK19-EI19 -> 0 | EK19: =+EB19+ED19+EF19+EE19 -> 0
B20: D&H United | C20: Windpoint | E20: =+'Aug 31'!G7 -> 201000 | F20: =+G20-E20 -> -117250 | G20: =+'AR Calculation - Service'!AM278 -> 83750 | I20: =+'AR Calculation - Service'!AN277 -> 51925 | L20: =+'Sep 30'!G9 -> 201000 | M20: =+N20-L20 -> -65325 | N20: =+G20+I20+J20 -> 135675 | P20: 51925 | Q20: =-'Oct Collections'!J10-'Oct Collections'!J11 -> -134000 | S20: =+'Oct 31'!G9 -> 134000 | T20: =+U20-S20 -> -80400 | U20: =+N20+P20+Q20 -> 53600 | W20: =+'AR Calculation - Service'!AP277 -> 51925 | X20: =+'Nov Collections'!I50 -> -67000 | Z20: =+'Nov 30'!G9 -> 134000 | AA20: =+AB20-Z20 -> -95475 | AB20: =+U20+W20+X20 -> 38525 | AD20: =+'AR Calculation - Service'!AQ277 -> 95475 | AG20: =+'AR Calculation - Service'!AQ276 -> -67000 | AI20: =+'Dec 31'!G9 -> 67000 | AJ20: =+AK20-AI20 -> 0 | AK20: =+AB20+AD20+AG20+AF20+AE20 -> 67000 | AM20: 0 | AO20: =-'Oct Collections'!AF15-'Oct Collections'!AF16 -> 0 | AQ20: =+AI20+AN20+AO20 -> 67000 | AR20: =+AS20-AQ20 -> 0 | AS20: =+AK20+AM20+AO20+AN20 -> 67000 | AU20: 0 | AW20: =-'Oct Collections'!AN15-'Oct Collections'!AN16 -> 0 | AY20: =+AQ20+AV20+AW20 -> 67000 | AZ20: =+BA20-AY20 -> 0 | BA20: =+AS20+AU20+AW20+AV20 -> 67000 | BC20: 0 | BG20: =+AY20+BD20+BE20 -> 67000 | BH20: =+BI20-BG20 -> 0 | BI20: =+BA20+BC20+BE20+BD20 -> 67000 | BM20: =+'AR Calculation - Service'!AU276 -> -67000 | BO20: =+BG20+BL20+BM20 -> 0 | BP20: =+BQ20-BO20 -> 0 | BQ20: =+BI20+BK20+BM20+BL20 -> 0 | BS20: =BV20-BT20 -> 0 | BT20: 0 | BU20: 0 | BV20: =SUMIFS('Contract Data'!IP:IP,'Contract Data'!C:C,'Summary Rollforward'!B20) -> 0 | BX20: =+BO20+BT20+BU20 -> 0 | BY20: =+BZ20-BX20 -> 0 | BZ20: =+BQ20+BS20+BU20+BT20 -> 0 | CB20: =CE20-CC20 -> 0 | CC20: =SUMIFS('June 25 Inv'!G:G,'June 25 Inv'!D:D,'Summary Rollforward'!$B20) -> 0 | CD20: =-SUMIFS('Jun25 Dep'!I:I,'Jun25 Dep'!F:F,'Summary Rollforward'!$B20) -> 0 | CE20: =SUMIFS('Contract Data'!IQ:IQ,'Contract Data'!$C:$C,'Summary Rollforward'!$B20) -> 0 | CG20: =+BX20+CC20+CD20 -> 0 | CH20: =+CI20-CG20 -> 0 | CI20: =+BZ20+CB20+CD20+CC20 -> 0 | CK20: =CN20-CL20 -> 0 | CL20: =SUMIFS('Jul 25 Inv'!H:H,'Jul 25 Inv'!E:E,'Summary Rollforward'!$B20) -> 0 | CM20: =-SUMIFS('Jul25 Dep'!J:J,'Jul25 Dep'!F:F,'Summary Rollforward'!$B20) -> 0 | CN20: =SUMIFS('Contract Data'!IR:IR,'Contract Data'!$C:$C,'Summary Rollforward'!$B20) -> 0 | CP20: =+CG20+CL20+CM20 -> 0 | CQ20: =+CR20-CP20 -> 0 | CR20: =+CI20+CK20+CM20+CL20 -> 0 | CT20: =CW20-CU20 -> 0 | CU20: =SUMIFS('Aug 25 Inv'!H:H,'Aug 25 Inv'!E:E,'Summary Rollforward'!$B20) -> 0 | CV20: =-SUMIFS('Aug25 Dep'!J:J,'Aug25 Dep'!F:F,'Summary Rollforward'!$B20) -> 0 | CW20: =SUMIFS('Contract Data'!IS:IS,'Contract Data'!$C:$C,'Summary Rollforward'!$B20) -> 0 | CY20: =+CP20+CU20+CV20 -> 0 | CZ20: =+DA20-CY20 -> 0 | DA20: =+CR20+CT20+CV20+CU20 -> 0 | DC20: =DF20-DD20 -> 0 | DD20: =SUMIFS('Sep 25 Inv'!H:H,'Sep 25 Inv'!E:E,'Summary Rollforward'!$B20) -> 0 | DE20: =-SUMIFS('Sep25 Dep'!J:J,'Sep25 Dep'!F:F,'Summary Rollforward'!$B20) -> 0 | DF20: =SUMIFS('Contract Data'!IT:IT,'Contract Data'!$C:$C,'Summary Rollforward'!$B20) -> 0 | DH20: =+CY20+DD20+DE20 -> 0 | DI20: =+DJ20-DH20 -> 0 | DJ20: =+DA20+DC20+DE20+DD20 -> 0 | DL20: =DO20-DM20 -> 0 | DM20: =SUMIFS('Oct 25 Inv'!H:H,'Oct 25 Inv'!E:E,'Summary Rollforward'!$B20) -> 0 | DN20: =-SUMIFS('Oct25 Dep'!J:J,'Oct25 Dep'!F:F,'Summary Rollforward'!$B20) -> 0 | DO20: =SUMIFS('Contract Data'!IU:IU,'Contract Data'!$C:$C,'Summary Rollforward'!$B20) -> 0 | DQ20: =+DH20+DM20+DN20 -> 0 | DR20: =+DS20-DQ20 -> 0 | DS20: =+DJ20+DL20+DN20+DM20 -> 0 | DU20: =DX20-DV20 -> 0 | DV20: =SUMIFS('Nov 25 Inv'!H:H,'Nov 25 Inv'!E:E,'Summary Rollforward'!$B20) -> 0 | DW20: =-SUMIFS('Nov25 Dep'!J:J,'Nov25 Dep'!F:F,'Summary Rollforward'!$B20) -> 0 | DX20: =SUMIFS('Contract Data'!IV:IV,'Contract Data'!$C:$C,'Summary Rollforward'!$B20) -> 0 | DZ20: =+DQ20+DV20+DW20 -> 0 | EA20: =+EB20-DZ20 -> 0 | EB20: =+DS20+DU20+DW20+DV20 -> 0 | ED20: =EG20-EE20 -> 0 | EE20: =SUMIFS('Dec 25 Inv'!H:H,'Dec 25 Inv'!E:E,'Summary Rollforward'!$B20) -> 0 | EF20: =-SUMIFS('Dec25 Dep'!I:I,'Dec25 Dep'!F:F,'Summary Rollforward'!$B20) -> 0 | EG20: =SUMIFS('Contract Data'!IW:IW,'Contract Data'!$C:$C,'Summary Rollforward'!$B20) -> 0 | EI20: =+DZ20+EE20+EF20 -> 0 | EJ20: =+EK20-EI20 -> 0 | EK20: =+EB20+ED20+EF20+EE20 -> 0
B21: Double B Foods | C21: Anderson Group | DC21: =DF21-DD21 -> 13562.5 | DD21: =SUMIFS('Sep 25 Inv'!H:H,'Sep 25 Inv'!E:E,'Summary Rollforward'!$B21) -> 0 | DE21: =-SUMIFS('Sep25 Dep'!J:J,'Sep25 Dep'!F:F,'Summary Rollforward'!$B21) -> 0 | DF21: =SUMIFS('Contract Data'!IT:IT,'Contract Data'!$C:$C,'Summary Rollforward'!$B21) -> 13562.5 | DH21: =+CY21+DD21+DE21 -> 0 | DI21: =+DJ21-DH21 -> 13562.5 | DJ21: =+DA21+DC21+DE21+DD21 -> 13562.5 | DL21: =DO21-DM21 -> 13562.5 | DM21: =SUMIFS('Oct 25 Inv'!H:H,'Oct 25 Inv'!E:E,'Summary Rollforward'!$B21) -> 0 | DN21: =-SUMIFS('Oct25 Dep'!J:J,'Oct25 Dep'!F:F,'Summary Rollforward'!$B21) -> 0 | DO21: =SUMIFS('Contract Data'!IU:IU,'Contract Data'!$C:$C,'Summary Rollforward'!$B21) -> 13562.5 | DQ21: =+DH21+DM21+DN21 -> 0 | DR21: =+DS21-DQ21 -> 27125 | DS21: =+DJ21+DL21+DN21+DM21 -> 27125 | DU21: =DX21-DV21 -> -9625 | DV21: =SUMIFS('Nov 25 Inv'!H:H,'Nov 25 Inv'!E:E,'Summary Rollforward'!$B21) -> 36750 | DW21: =-SUMIFS('Nov25 Dep'!J:J,'Nov25 Dep'!F:F,'Summary Rollforward'!$B21) -> -36750 | DX21: =SUMIFS('Contract Data'!IV:IV,'Contract Data'!$C:$C,'Summary Rollforward'!$B21) -> 27125 | DZ21: =+DQ21+DV21+DW21 -> 0 | EA21: =+EB21-DZ21 -> 17500 | EB21: =+DS21+DU21+DW21+DV21 -> 17500 | ED21: =EG21-EE21 -> -3941.42 | EE21: =SUMIFS('Dec 25 Inv'!H:H,'Dec 25 Inv'!E:E,'Summary Rollforward'!$B21) -> 41303.7 | EF21: =-SUMIFS('Dec25 Dep'!I:I,'Dec25 Dep'!F:F,'Summary Rollforward'!$B21) -> 0 | EG21: =SUMIFS('Contract Data'!IW:IW,'Contract Data'!$C:$C,'Summary Rollforward'!$B21) -> 37362.28 | EI21: =+DZ21+EE21+EF21 -> 41303.7 | EJ21: =+EK21-EI21 -> 13558.58 | EK21: =+EB21+ED21+EF21+EE21 -> 54862.28
B22: Douglas Washing & Sanitizing | C22: LLCP | P22: 46500 | S22: 0 | U22: =+N22+P22+Q22 -> 46500 | W22: =+'AR Calculation - Service'!AP297 -> 46500 | Z22: =+'Nov 30'!G10 -> 50000 | AA22: =+AB22-Z22 -> 43000 | AB22: =+U22+W22+X22 -> 93000 | AD22: =+'AR Calculation - Service'!AQ297-AE22 -> -34965 | AE22: =+'Dec Invoicing'!I16 -> 50000 | AG22: =+'AR Calculation - Service'!AQ296 -> -50000 | AI22: =+'Dec 31'!G10 -> 50000 | AJ22: =+AK22-AI22 -> 8035 | AK22: =+AB22+AD22+AG22+AF22+AE22 -> 58035 | AM22: =+'AR Calculation - Service'!AR297-'Summary Rollforward'!AN22 -> -12201 | AN22: =+'Jan Invoicing'!G10 -> 53868 | AO22: =-'Oct Collections'!AF16-'Oct Collections'!AF17 -> 0 | AQ22: =+AI22+AN22+AO22 -> 103868 | AR22: =+AS22-AQ22 -> -4166 | AS22: =+AK22+AM22+AO22+AN22 -> 99702 | AU22: =+'AR Calculation - Service'!AS297-'Summary Rollforward'!AV22 -> 41667 | AV22: =+'Jan Invoicing'!O10 -> 0 | AW22: =-'Oct Collections'!AN16-'Oct Collections'!AN17 -> 0 | AY22: =+AQ22+AV22+AW22 -> 103868 | AZ22: =+BA22-AY22 -> 37501 | BA22: =+AS22+AU22+AW22+AV22 -> 141369 | BC22: =+'AR Calculation - Service'!AT297-'Summary Rollforward'!BD22 -> 41667 | BD22: =+'Jan Invoicing'!W10 -> 0 | BG22: =+AY22+BD22+BE22 -> 103868 | BH22: =+BI22-BG22 -> 79168 | BI22: =+BA22+BC22+BE22+BD22 -> 183036 | BO22: =+BG22+BL22+BM22 -> 103868 | BP22: =+BQ22-BO22 -> 79168 | BQ22: =+BI22+BK22+BM22+BL22 -> 183036 | BS22: =BV22-BT22 -> -50000 | BT22: 50000 | BU22: -103868 | BV22: =SUMIFS('Contract Data'!IP:IP,'Contract Data'!C:C,'Summary Rollforward'!B22) -> 0 | BX22: =+BO22+BT22+BU22 -> 50000 | BY22: =+BZ22-BX22 -> 29168 | BZ22: =+BQ22+BS22+BU22+BT22 -> 79168 | CB22: =CE22-CC22 -> 0 | CC22: =SUMIFS('June 25 Inv'!G:G,'June 25 Inv'!D:D,'Summary Rollforward'!$B22) -> 0 | CD22: =-SUMIFS('Jun25 Dep'!I:I,'Jun25 Dep'!F:F,'Summary Rollforward'!$B22) -> 0 | CE22: =SUMIFS('Contract Data'!IQ:IQ,'Contract Data'!$C:$C,'Summary Rollforward'!$B22) -> 0 | CG22: =+BX22+CC22+CD22 -> 50000 | CH22: =+CI22-CG22 -> 29168 | CI22: =+BZ22+CB22+CD22+CC22 -> 79168 | CK22: =CN22-CL22 -> -29168 | CL22: =SUMIFS('Jul 25 Inv'!H:H,'Jul 25 Inv'!E:E,'Summary Rollforward'!$B22) -> 50000 | CM22: =-SUMIFS('Jul25 Dep'!J:J,'Jul25 Dep'!F:F,'Summary Rollforward'!$B22) -> -50000 | CN22: =SUMIFS('Contract Data'!IR:IR,'Contract Data'!$C:$C,'Summary Rollforward'!$B22) -> 20832 | CP22: =+CG22+CL22+CM22 -> 50000 | CQ22: =+CR22-CP22 -> 0 | CR22: =+CI22+CK22+CM22+CL22 -> 50000 | CT22: =CW22-CU22 -> 0 | CU22: =SUMIFS('Aug 25 Inv'!H:H,'Aug 25 Inv'!E:E,'Summary Rollforward'!$B22) -> 0 | CV22: =-SUMIFS('Aug25 Dep'!J:J,'Aug25 Dep'!F:F,'Summary Rollforward'!$B22) -> -50000 | CW22: =SUMIFS('Contract Data'!IS:IS,'Contract Data'!$C:$C,'Summary Rollforward'!$B22) -> 0 | CY22: =+CP22+CU22+CV22 -> 0 | CZ22: =+DA22-CY22 -> 0 | DA22: =+CR22+CT22+CV22+CU22 -> 0 | DC22: =DF22-DD22 -> 0 | DD22: =SUMIFS('Sep 25 Inv'!H:H,'Sep 25 Inv'!E:E,'Summary Rollforward'!$B22) -> 0 | DE22: =-SUMIFS('Sep25 Dep'!J:J,'Sep25 Dep'!F:F,'Summary Rollforward'!$B22) -> 0 | DF22: =SUMIFS('Contract Data'!IT:IT,'Contract Data'!$C:$C,'Summary Rollforward'!$B22) -> 0 | DH22: =+CY22+DD22+DE22 -> 0 | DI22: =+DJ22-DH22 -> 0 | DJ22: =+DA22+DC22+DE22+DD22 -> 0 | DL22: =DO22-DM22 -> 0 | DM22: =SUMIFS('Oct 25 Inv'!H:H,'Oct 25 Inv'!E:E,'Summary Rollforward'!$B22) -> 0 | DN22: =-SUMIFS('Oct25 Dep'!J:J,'Oct25 Dep'!F:F,'Summary Rollforward'!$B22) -> 0 | DO22: =SUMIFS('Contract Data'!IU:IU,'Contract Data'!$C:$C,'Summary Rollforward'!$B22) -> 0 | DQ22: =+DH22+DM22+DN22 -> 0 | DR22: =+DS22-DQ22 -> 0 | DS22: =+DJ22+DL22+DN22+DM22 -> 0 | DU22: =DX22-DV22 -> 0 | DV22: =SUMIFS('Nov 25 Inv'!H:H,'Nov 25 Inv'!E:E,'Summary Rollforward'!$B22) -> 0 | DW22: =-SUMIFS('Nov25 Dep'!J:J,'Nov25 Dep'!F:F,'Summary Rollforward'!$B22) -> 0 | DX22: =SUMIFS('Contract Data'!IV:IV,'Contract Data'!$C:$C,'Summary Rollforward'!$B22) -> 0 | DZ22: =+DQ22+DV22+DW22 -> 0 | EA22: =+EB22-DZ22 -> 0 | EB22: =+DS22+DU22+DW22+DV22 -> 0 | ED22: =EG22-EE22 -> 0 | EE22: =SUMIFS('Dec 25 Inv'!H:H,'Dec 25 Inv'!E:E,'Summary Rollforward'!$B22) -> 0 | EF22: =-SUMIFS('Dec25 Dep'!I:I,'Dec25 Dep'!F:F,'Summary Rollforward'!$B22) -> 0 | EG22: =SUMIFS('Contract Data'!IW:IW,'Contract Data'!$C:$C,'Summary Rollforward'!$B22) -> 0 | EI22: =+DZ22+EE22+EF22 -> 0 | EJ22: =+EK22-EI22 -> 0 | EK22: =+EB22+ED22+EF22+EE22 -> 0
B23: Emerald Technologies | C23: Crestview Partners | BK23: =+'AR Calculation - Service'!AU385-'Summary Rollforward'!BL23 -> -12375 | BL23: =+'Apr Invoices'!G19 -> 55000 | BO23: =+BG23+BL23+BM23 -> 55000 | BP23: =+BQ23-BO23 -> -12375 | BQ23: =+BI23+BK23+BM23+BL23 -> 42625 | BS23: =BV23-BT23 -> -12375 | BT23: 55000 | BU23: 0 | BV23: =SUMIFS('Contract Data'!IP:IP,'Contract Data'!C:C,'Summary Rollforward'!B23) -> 42625 | BX23: =+BO23+BT23+BU23 -> 110000 | BY23: =+BZ23-BX23 -> -24750 | BZ23: =+BQ23+BS23+BU23+BT23 -> 85250 | CB23: =CE23-CC23 -> -12375 | CC23: =SUMIFS('June 25 Inv'!G:G,'June 25 Inv'!D:D,'Summary Rollforward'!$B23) -> 55000 | CD23: =-SUMIFS('Jun25 Dep'!I:I,'Jun25 Dep'!F:F,'Summary Rollforward'!$B23) -> 0 | CE23: =SUMIFS('Contract Data'!IQ:IQ,'Contract Data'!$C:$C,'Summary Rollforward'!$B23) -> 42625 | CG23: =+BX23+CC23+CD23 -> 165000 | CH23: =+CI23-CG23 -> -37125 | CI23: =+BZ23+CB23+CD23+CC23 -> 127875 | CK23: =CN23-CL23 -> -12375 | CL23: =SUMIFS('Jul 25 Inv'!H:H,'Jul 25 Inv'!E:E,'Summary Rollforward'!$B23) -> 55000 | CM23: =-SUMIFS('Jul25 Dep'!J:J,'Jul25 Dep'!F:F,'Summary Rollforward'!$B23) -> -55000 | CN23: =SUMIFS('Contract Data'!IR:IR,'Contract Data'!$C:$C,'Summary Rollforward'!$B23) -> 42625 | CP23: =+CG23+CL23+CM23 -> 165000 | CQ23: =+CR23-CP23 -> -49500 | CR23: =+CI23+CK23+CM23+CL23 -> 115500 | CT23: =CW23-CU23 -> -12375 | CU23: =SUMIFS('Aug 25 Inv'!H:H,'Aug 25 Inv'!E:E,'Summary Rollforward'!$B23) -> 55000 | CV23: =-SUMIFS('Aug25 Dep'!J:J,'Aug25 Dep'!F:F,'Summary Rollforward'!$B23) -> -110000 | CW23: =SUMIFS('Contract Data'!IS:IS,'Contract Data'!$C:$C,'Summary Rollforward'!$B23) -> 42625 | CY23: =+CP23+CU23+CV23 -> 110000 | CZ23: =+DA23-CY23 -> -61875 | DA23: =+CR23+CT23+CV23+CU23 -> 48125 | DC23: =DF23-DD23 -> 15000 | DD23: =SUMIFS('Sep 25 Inv'!H:H,'Sep 25 Inv'!E:E,'Summary Rollforward'!$B23) -> 0 | DE23: =-SUMIFS('Sep25 Dep'!J:J,'Sep25 Dep'!F:F,'Summary Rollforward'!$B23) -> -55000 | DF23: =SUMIFS('Contract Data'!IT:IT,'Contract Data'!$C:$C,'Summary Rollforward'!$B23) -> 15000 | DH23: =+CY23+DD23+DE23 -> 55000 | DI23: =+DJ23-DH23 -> -46875 | DJ23: =+DA23+DC23+DE23+DD23 -> 8125 | DL23: =DO23-DM23 -> 15000 | DM23: =SUMIFS('Oct 25 Inv'!H:H,'Oct 25 Inv'!E:E,'Summary Rollforward'!$B23) -> 0 | DN23: =-SUMIFS('Oct25 Dep'!J:J,'Oct25 Dep'!F:F,'Summary Rollforward'!$B23) -> 0 | DO23: =SUMIFS('Contract Data'!IU:IU,'Contract Data'!$C:$C,'Summary Rollforward'!$B23) -> 15000 | DQ23: =+DH23+DM23+DN23 -> 55000 | DR23: =+DS23-DQ23 -> -31875 | DS23: =+DJ23+DL23+DN23+DM23 -> 23125 | DU23: =DX23-DV23 -> 15000 | DV23: =SUMIFS('Nov 25 Inv'!H:H,'Nov 25 Inv'!E:E,'Summary Rollforward'!$B23) -> 0 | DW23: =-SUMIFS('Nov25 Dep'!J:J,'Nov25 Dep'!F:F,'Summary Rollforward'!$B23) -> 0 | DX23: =SUMIFS('Contract Data'!IV:IV,'Contract Data'!$C:$C,'Summary Rollforward'!$B23) -> 15000 | DZ23: =+DQ23+DV23+DW23 -> 55000 | EA23: =+EB23-DZ23 -> -16875 | EB23: =+DS23+DU23+DW23+DV23 -> 38125 | ED23: =EG23-EE23 -> 5625 | EE23: =SUMIFS('Dec 25 Inv'!H:H,'Dec 25 Inv'!E:E,'Summary Rollforward'!$B23) -> 0 | EF23: =-SUMIFS('Dec25 Dep'!I:I,'Dec25 Dep'!F:F,'Summary Rollforward'!$B23) -> 0 | EG23: =SUMIFS('Contract Data'!IW:IW,'Contract Data'!$C:$C,'Summary Rollforward'!$B23) -> 5625 | EI23: =+DZ23+EE23+EF23 -> 55000 | EJ23: =+EK23-EI23 -> -11250 | EK23: =+EB23+ED23+EF23+EE23 -> 43750
B24: Enerpac Tool Group | C24: NA | BK24: =+'AR Calculation - Service'!AU389-'Summary Rollforward'!BL24 -> -50000 | BL24: 50000 | BO24: =+BG24+BL24+BM24 -> 50000 | BP24: =+BQ24-BO24 -> -50000 | BQ24: =+BI24+BK24+BM24+BL24 -> 0 | BS24: =BV24-BT24 -> 0 | BT24: 0 | BU24: 0 | BV24: =SUMIFS('Contract Data'!IP:IP,'Contract Data'!C:C,'Summary Rollforward'!B24) -> 0 | BX24: =+BO24+BT24+BU24 -> 50000 | BY24: =+BZ24-BX24 -> -50000 | BZ24: =+BQ24+BS24+BU24+BT24 -> 0 | CB24: =CE24-CC24 -> 0 | CC24: =SUMIFS('June 25 Inv'!G:G,'June 25 Inv'!D:D,'Summary Rollforward'!$B24) -> 0 | CD24: =-SUMIFS('Jun25 Dep'!I:I,'Jun25 Dep'!F:F,'Summary Rollforward'!$B24) -> 0 | CE24: =SUMIFS('Contract Data'!IQ:IQ,'Contract Data'!$C:$C,'Summary Rollforward'!$B24) -> 0 | CG24: =+BX24+CC24+CD24 -> 50000 | CH24: =+CI24-CG24 -> -50000 | CI24: =+BZ24+CB24+CD24+CC24 -> 0 | CK24: =CN24-CL24 -> 15000 | CL24: =SUMIFS('Jul 25 Inv'!H:H,'Jul 25 Inv'!E:E,'Summary Rollforward'!$B24) -> 0 | CM24: =-SUMIFS('Jul25 Dep'!J:J,'Jul25 Dep'!F:F,'Summary Rollforward'!$B24) -> 0 | CN24: =SUMIFS('Contract Data'!IR:IR,'Contract Data'!$C:$C,'Summary Rollforward'!$B24) -> 15000 | CP24: =+CG24+CL24+CM24 -> 50000 | CQ24: =+CR24-CP24 -> -35000 | CR24: =+CI24+CK24+CM24+CL24 -> 15000 | CT24: =CW24-CU24 -> 15000 | CU24: =SUMIFS('Aug 25 Inv'!H:H,'Aug 25 Inv'!E:E,'Summary Rollforward'!$B24) -> 0 | CV24: =-SUMIFS('Aug25 Dep'!J:J,'Aug25 Dep'!F:F,'Summary Rollforward'!$B24) -> 0 | CW24: =SUMIFS('Contract Data'!IS:IS,'Contract Data'!$C:$C,'Summary Rollforward'!$B24) -> 15000 | CY24: =+CP24+CU24+CV24 -> 50000 | CZ24: =+DA24-CY24 -> -20000 | DA24: =+CR24+CT24+CV24+CU24 -> 30000 | DC24: =DF24-DD24 -> 60000 | DD24: =SUMIFS('Sep 25 Inv'!H:H,'Sep 25 Inv'!E:E,'Summary Rollforward'!$B24) -> 0 | DE24: =-SUMIFS('Sep25 Dep'!J:J,'Sep25 Dep'!F:F,'Summary Rollforward'!$B24) -> -50000 | DF24: =SUMIFS('Contract Data'!IT:IT,'Contract Data'!$C:$C,'Summary Rollforward'!$B24) -> 60000 | DH24: =+CY24+DD24+DE24 -> 0 | DI24: =+DJ24-DH24 -> 40000 | DJ24: =+DA24+DC24+DE24+DD24 -> 40000 | DL24: =DO24-DM24 -> 60000 | DM24: =SUMIFS('Oct 25 Inv'!H:H,'Oct 25 Inv'!E:E,'Summary Rollforward'!$B24) -> 0 | DN24: =-SUMIFS('Oct25 Dep'!J:J,'Oct25 Dep'!F:F,'Summary Rollforward'!$B24) -> 0 | DO24: =SUMIFS('Contract Data'!IU:IU,'Contract Data'!$C:$C,'Summary Rollforward'!$B24) -> 60000 | DQ24: =+DH24+DM24+DN24 -> 0 | DR24: =+DS24-DQ24 -> 100000 | DS24: =+DJ24+DL24+DN24+DM24 -> 100000 | DU24: =DX24-DV24 -> 60000 | DV24: =SUMIFS('Nov 25 Inv'!H:H,'Nov 25 Inv'!E:E,'Summary Rollforward'!$B24) -> 0 | DW24: =-SUMIFS('Nov25 Dep'!J:J,'Nov25 Dep'!F:F,'Summary Rollforward'!$B24) -> 0 | DX24: =SUMIFS('Contract Data'!IV:IV,'Contract Data'!$C:$C,'Summary Rollforward'!$B24) -> 60000 | DZ24: =+DQ24+DV24+DW24 -> 0 | EA24: =+EB24-DZ24 -> 160000 | EB24: =+DS24+DU24+DW24+DV24 -> 160000 | ED24: =EG24-EE24 -> 45396.33 | EE24: =SUMIFS('Dec 25 Inv'!H:H,'Dec 25 Inv'!E:E,'Summary Rollforward'!$B24) -> 14603.67 | EF24: =-SUMIFS('Dec25 Dep'!I:I,'Dec25 Dep'!F:F,'Summary Rollforward'!$B24) -> 0 | EG24: =SUMIFS('Contract Data'!IW:IW,'Contract Data'!$C:$C,'Summary Rollforward'!$B24) -> 60000 | EI24: =+DZ24+EE24+EF24 -> 14603.67 | EJ24: =+EK24-EI24 -> 205396.33 | EK24: =+EB24+ED24+EF24+EE24 -> 220000
